[32mINFO    [0m integration.ha.test_backups:test_backups.py:440 Syncing credentials for aws
[32mINFO    [0m juju.model:model.py:2971 Waiting for model:
  main/0 [executing] maintenance: Configuring backup service...
  s3-integrator/0 [idle] active: 
[32mINFO    [0m juju.model:model.py:2971 Waiting for model:
  main/0 [idle] active: 
[32mINFO    [0m integration.helpers:helpers.py:367 Calling: GET -- https://10.13.13.207:9200/_recovery?human
[32mINFO    [0m integration.ha.helpers:helpers.py:247 Continuous writes result: namespace(max_stored_id=182, count=183, last_expected_id=182)
[32mINFO    [0m integration.helpers:helpers.py:367 Calling: GET -- https://10.13.13.207:9200/series_index/_search_shards
[32mINFO    [0m integration.helpers:helpers.py:367 Calling: POST -- https://10.13.13.207:9200/series_index/_refresh
[32mINFO    [0m integration.helpers:helpers.py:367 Calling: GET -- https://10.13.13.207:9200/series_index/_count
[32mINFO    [0m integration.helpers:helpers.py:367 Calling: GET -- https://10.13.13.207:9200/_recovery?human
[32mINFO    [0m integration.helpers:helpers.py:367 Calling: POST -- https://10.13.13.207:9200/series_index/_refresh
[32mINFO    [0m integration.helpers:helpers.py:367 Calling: GET -- https://10.13.13.207:9200/series_index/_count
[32mINFO    [0m integration.ha.helpers:helpers.py:591 Testing restore for series_index - original count pre-restore: 183, and now, new count: 153
[32mINFO    [0m integration.helpers:helpers.py:367 Calling: POST -- https://10.13.13.207:9200/series_index/_refresh
[32mINFO    [0m integration.helpers:helpers.py:367 Calling: GET -- https://10.13.13.207:9200/series_index/_count
[32mINFO    [0m integration.ha.conftest:conftest.py:39 



The writes have been cleared.