[32mINFO    [0m pytest_operator.plugin:plugin.py:862 Model status:

Model  Controller           Cloud/Region         Version  SLA          Timestamp
test   localhost-localhost  localhost/localhost  3.5.3    unsupported  03:44:11Z

App                       Version  Status   Scale  Charm                     Channel        Rev  Exposed  Message
failover                           active       2  opensearch                                 0  no       
main                               active       1  opensearch                                 1  no       
opensearch                         active       1  opensearch                                 2  no       
s3-integrator                      blocked      1  s3-integrator             latest/edge     41  no       Missing parameters: ['access-key', 'secret-key']
self-signed-certificates           active       1  self-signed-certificates  latest/stable  155  no       

Unit                         Workload  Agent  Machine  Public address  Ports     Message
failover/0*                  error     idle   2        10.146.119.122  9200/tcp  hook failed: "certificates-relation-changed"
failover/1                   active    idle   3        10.146.119.48   9200/tcp  
main/0*                      active    idle   4        10.146.119.78   9200/tcp  
opensearch/0*                active    idle   5        10.146.119.50   9200/tcp  
s3-integrator/0*             blocked   idle   0        10.146.119.19             Missing parameters: ['access-key', 'secret-key']
self-signed-certificates/0*  active    idle   1        10.146.119.22             

Machine  State    Address         Inst id        Base          AZ  Message
0        started  10.146.119.19   juju-5ddd1a-0  ubuntu@22.04      Running
1        started  10.146.119.22   juju-5ddd1a-1  ubuntu@22.04      Running
2        started  10.146.119.122  juju-5ddd1a-2  ubuntu@22.04      Running
3        started  10.146.119.48   juju-5ddd1a-3  ubuntu@22.04      Running
4        started  10.146.119.78   juju-5ddd1a-4  ubuntu@22.04      Running
5        started  10.146.119.50   juju-5ddd1a-5  ubuntu@22.04      Running

[32mINFO    [0m pytest_operator.plugin:plugin.py:868 Juju error logs:

machine-1: 02:45:30 ERROR juju.worker.dependency "lxd-container-provisioner" manifold worker returned unexpected error: container types not yet available
machine-1: 02:45:30 ERROR juju.worker.dependency "kvm-container-provisioner" manifold worker returned unexpected error: container types not yet available
unit-self-signed-certificates-0: 02:45:30 ERROR juju.worker.meterstatus error running "meter-status-changed": charm missing from disk
machine-0: 02:45:33 ERROR juju.worker.dependency "lxd-container-provisioner" manifold worker returned unexpected error: container types not yet available
machine-0: 02:45:33 ERROR juju.worker.dependency "kvm-container-provisioner" manifold worker returned unexpected error: container types not yet available
unit-s3-integrator-0: 02:45:34 ERROR juju.worker.meterstatus error running "meter-status-changed": charm missing from disk
machine-4: 02:45:46 ERROR juju.worker.dependency "lxd-container-provisioner" manifold worker returned unexpected error: container types not yet available
machine-4: 02:45:46 ERROR juju.worker.dependency "kvm-container-provisioner" manifold worker returned unexpected error: container types not yet available
unit-main-0: 02:45:46 ERROR juju.worker.meterstatus error running "meter-status-changed": charm missing from disk
machine-2: 02:45:48 ERROR juju.worker.dependency "kvm-container-provisioner" manifold worker returned unexpected error: container types not yet available
machine-2: 02:45:48 ERROR juju.worker.dependency "lxd-container-provisioner" manifold worker returned unexpected error: container types not yet available
unit-failover-0: 02:45:48 ERROR juju.worker.meterstatus error running "meter-status-changed": charm missing from disk
machine-5: 02:45:48 ERROR juju.worker.dependency "lxd-container-provisioner" manifold worker returned unexpected error: container types not yet available
machine-5: 02:45:48 ERROR juju.worker.dependency "kvm-container-provisioner" manifold worker returned unexpected error: container types not yet available
unit-opensearch-0: 02:45:48 ERROR juju.worker.meterstatus error running "meter-status-changed": charm missing from disk
machine-3: 02:45:55 ERROR juju.worker.dependency "lxd-container-provisioner" manifold worker returned unexpected error: container types not yet available
machine-3: 02:45:55 ERROR juju.worker.dependency "kvm-container-provisioner" manifold worker returned unexpected error: container types not yet available
unit-failover-1: 02:45:55 ERROR juju.worker.meterstatus error running "meter-status-changed": charm missing from disk
unit-failover-1: 02:47:31 ERROR unit.failover/1.juju-log [Errno 111] Connection refused
unit-opensearch-0: 02:47:31 ERROR unit.opensearch/0.juju-log [Errno 111] Connection refused
unit-main-0: 02:47:31 ERROR unit.main/0.juju-log [Errno 111] Connection refused
unit-failover-1: 02:47:32 ERROR unit.failover/1.juju-log peer-cluster:10: [Errno 111] Connection refused
unit-opensearch-0: 02:47:32 ERROR unit.opensearch/0.juju-log peer-cluster:11: [Errno 111] Connection refused
unit-main-0: 02:47:32 ERROR unit.main/0.juju-log certificates:13: [Errno 111] Connection refused
unit-failover-1: 02:47:33 ERROR unit.failover/1.juju-log certificates:14: [Errno 111] Connection refused
unit-opensearch-0: 02:47:33 ERROR unit.opensearch/0.juju-log peer-cluster:11: [Errno 111] Connection refused
unit-main-0: 02:47:33 ERROR unit.main/0.juju-log opensearch-peers:6: [Errno 111] Connection refused
unit-main-0: 02:47:34 ERROR unit.main/0.juju-log opensearch-peers:6: [Errno 111] Connection refused
unit-main-0: 02:47:34 ERROR unit.main/0.juju-log opensearch-peers:6: [Errno 111] Connection refused
unit-main-0: 02:47:34 ERROR unit.main/0.juju-log opensearch-peers:6: [Errno 111] Connection refused
unit-failover-1: 02:47:34 ERROR unit.failover/1.juju-log certificates:14: [Errno 111] Connection refused
unit-opensearch-0: 02:47:34 ERROR unit.opensearch/0.juju-log upgrade-version-a:8: [Errno 111] Connection refused
unit-main-0: 02:47:34 ERROR unit.main/0.juju-log certificates:13: [Errno 111] Connection refused
unit-failover-1: 02:47:35 ERROR unit.failover/1.juju-log peer-cluster:10: [Errno 111] Connection refused
unit-opensearch-0: 02:47:35 ERROR unit.opensearch/0.juju-log opensearch-peers:9: [Errno 111] Connection refused
unit-opensearch-0: 02:47:35 ERROR unit.opensearch/0.juju-log opensearch-peers:9: [Errno 111] Connection refused
unit-opensearch-0: 02:47:35 ERROR unit.opensearch/0.juju-log opensearch-peers:9: [Errno 111] Connection refused
unit-opensearch-0: 02:47:35 ERROR unit.opensearch/0.juju-log opensearch-peers:9: [Errno 111] Connection refused
unit-main-0: 02:47:35 ERROR unit.main/0.juju-log peer-cluster-orchestrator:10: [Errno 111] Connection refused
unit-failover-1: 02:47:36 ERROR unit.failover/1.juju-log peer-cluster-orchestrator:12: [Errno 111] Connection refused
unit-opensearch-0: 02:47:36 ERROR unit.opensearch/0.juju-log certificates:15: [Errno 111] Connection refused
unit-main-0: 02:47:36 ERROR unit.main/0.juju-log peer-cluster-orchestrator:10: [Errno 111] Connection refused
unit-failover-1: 02:47:37 ERROR unit.failover/1.juju-log peer-cluster:10: [Errno 111] Connection refused
unit-main-0: 02:47:37 ERROR unit.main/0.juju-log peer-cluster-orchestrator:11: [Errno 111] Connection refused
unit-failover-1: 02:47:38 ERROR unit.failover/1.juju-log peer-cluster-orchestrator:12: [Errno 111] Connection refused
unit-failover-1: 02:47:39 ERROR unit.failover/1.juju-log certificates:14: [Errno 111] Connection refused
unit-main-0: 02:47:39 ERROR unit.main/0.juju-log opensearch-peers:6: [Errno 111] Connection refused
unit-main-0: 02:47:39 ERROR unit.main/0.juju-log opensearch-peers:6: [Errno 111] Connection refused
unit-main-0: 02:47:39 ERROR unit.main/0.juju-log opensearch-peers:6: [Errno 111] Connection refused
unit-main-0: 02:47:39 ERROR unit.main/0.juju-log opensearch-peers:6: [Errno 111] Connection refused
unit-failover-1: 02:47:39 ERROR unit.failover/1.juju-log peer-cluster:10: [Errno 111] Connection refused
unit-main-0: 02:47:40 ERROR unit.main/0.juju-log peer-cluster-orchestrator:11: [Errno 111] Connection refused
unit-opensearch-0: 02:47:40 ERROR unit.opensearch/0.juju-log [Errno 111] Connection refused
unit-opensearch-0: 02:47:41 ERROR unit.opensearch/0.juju-log [Errno 111] Connection refused
unit-main-0: 02:47:41 ERROR unit.main/0.juju-log peer-cluster-orchestrator:11: [Errno 111] Connection refused
unit-opensearch-0: 02:47:42 ERROR unit.opensearch/0.juju-log peer-cluster:12: [Errno 111] Connection refused
unit-main-0: 02:47:42 ERROR unit.main/0.juju-log certificates:13: [Errno 111] Connection refused
unit-opensearch-0: 02:47:43 ERROR unit.opensearch/0.juju-log [Errno 111] Connection refused
unit-opensearch-0: 02:47:43 ERROR unit.opensearch/0.juju-log [Errno 111] Connection refused
unit-opensearch-0: 02:47:44 ERROR unit.opensearch/0.juju-log peer-cluster:11: [Errno 111] Connection refused
unit-opensearch-0: 02:47:45 ERROR unit.opensearch/0.juju-log certificates:15: [Errno 111] Connection refused
unit-main-0: 02:47:46 ERROR unit.main/0.juju-log [Errno 111] Connection refused
unit-opensearch-0: 02:47:46 ERROR unit.opensearch/0.juju-log certificates:15: [Errno 111] Connection refused
unit-main-0: 02:47:47 ERROR unit.main/0.juju-log [Errno 111] Connection refused
unit-failover-1: 02:47:48 ERROR unit.failover/1.juju-log peer-cluster:10: [Errno 111] Connection refused
unit-main-0: 02:47:48 ERROR unit.main/0.juju-log [Errno 111] Connection refused
unit-opensearch-0: 02:47:48 ERROR unit.opensearch/0.juju-log [Errno 111] Connection refused
unit-opensearch-0: 02:47:49 ERROR unit.opensearch/0.juju-log [Errno 111] Connection refused
unit-main-0: 02:47:49 ERROR unit.main/0.juju-log upgrade-version-a:5: [Errno 111] Connection refused
unit-main-0: 02:47:49 ERROR unit.main/0.juju-log upgrade-version-a:5: [Errno 111] Connection refused
unit-main-0: 02:47:49 ERROR unit.main/0.juju-log upgrade-version-a:5: Cannot connect to the OpenSearch server...
unit-main-0: 02:47:49 ERROR unit.main/0.juju-log upgrade-version-a:5: [Errno 111] Connection refused
unit-opensearch-0: 02:47:50 ERROR unit.opensearch/0.juju-log [Errno 111] Connection refused
unit-main-0: 02:47:50 ERROR unit.main/0.juju-log upgrade-version-a:5: [Errno 111] Connection refused
unit-main-0: 02:47:50 ERROR unit.main/0.juju-log upgrade-version-a:5: Cannot connect to the OpenSearch server...
unit-main-0: 02:47:50 ERROR unit.main/0.juju-log upgrade-version-a:5: [Errno 111] Connection refused
unit-main-0: 02:47:50 ERROR unit.main/0.juju-log upgrade-version-a:5: Cannot connect to the OpenSearch server...
unit-opensearch-0: 02:47:51 ERROR unit.opensearch/0.juju-log [Errno 111] Connection refused
unit-opensearch-0: 02:47:52 ERROR unit.opensearch/0.juju-log opensearch-peers:9: [Errno 111] Connection refused
unit-opensearch-0: 02:47:52 ERROR unit.opensearch/0.juju-log opensearch-peers:9: [Errno 111] Connection refused
unit-opensearch-0: 02:47:52 ERROR unit.opensearch/0.juju-log opensearch-peers:9: [Errno 111] Connection refused
unit-opensearch-0: 02:47:52 ERROR unit.opensearch/0.juju-log opensearch-peers:9: [Errno 111] Connection refused
unit-opensearch-0: 02:47:53 ERROR unit.opensearch/0.juju-log peer-cluster:11: [Errno 111] Connection refused
unit-main-0: 02:47:53 ERROR unit.main/0.juju-log upgrade-version-a:5: [Errno 111] Connection refused
unit-main-0: 02:47:53 ERROR unit.main/0.juju-log upgrade-version-a:5: Cannot connect to the OpenSearch server...
unit-opensearch-0: 02:47:54 ERROR unit.opensearch/0.juju-log peer-cluster:12: [Errno 111] Connection refused
unit-failover-1: 02:47:55 ERROR unit.failover/1.juju-log peer-cluster-orchestrator:12: [Errno 111] Connection refused
unit-opensearch-0: 02:47:55 ERROR unit.opensearch/0.juju-log opensearch-peers:9: [Errno 111] Connection refused
unit-opensearch-0: 02:47:55 ERROR unit.opensearch/0.juju-log opensearch-peers:9: [Errno 111] Connection refused
unit-opensearch-0: 02:47:55 ERROR unit.opensearch/0.juju-log opensearch-peers:9: [Errno 111] Connection refused
unit-opensearch-0: 02:47:55 ERROR unit.opensearch/0.juju-log opensearch-peers:9: [Errno 111] Connection refused
unit-main-0: 02:47:56 ERROR unit.main/0.juju-log upgrade-version-a:5: [Errno 111] Connection refused
unit-main-0: 02:47:56 ERROR unit.main/0.juju-log upgrade-version-a:5: Cannot connect to the OpenSearch server...
unit-main-0: 02:47:59 ERROR unit.main/0.juju-log upgrade-version-a:5: [Errno 111] Connection refused
unit-main-0: 02:47:59 ERROR unit.main/0.juju-log upgrade-version-a:5: Cannot connect to the OpenSearch server...
unit-main-0: 02:48:02 ERROR unit.main/0.juju-log upgrade-version-a:5: [Errno 111] Connection refused
unit-main-0: 02:48:02 ERROR unit.main/0.juju-log upgrade-version-a:5: Cannot connect to the OpenSearch server...
unit-failover-1: 02:48:13 ERROR unit.failover/1.juju-log peer-cluster:10: [Errno 111] Connection refused
unit-opensearch-0: 02:48:14 ERROR unit.opensearch/0.juju-log peer-cluster:11: [Errno 111] Connection refused
unit-opensearch-0: 02:48:15 ERROR unit.opensearch/0.juju-log opensearch-peers:9: [Errno 111] Connection refused
unit-opensearch-0: 02:48:15 ERROR unit.opensearch/0.juju-log opensearch-peers:9: [Errno 111] Connection refused
unit-opensearch-0: 02:48:15 ERROR unit.opensearch/0.juju-log opensearch-peers:9: [Errno 111] Connection refused
unit-opensearch-0: 02:48:15 ERROR unit.opensearch/0.juju-log opensearch-peers:9: [Errno 111] Connection refused
unit-opensearch-0: 02:48:23 ERROR unit.opensearch/0.juju-log peer-cluster:11: [Errno 111] Connection refused
unit-failover-1: 02:48:23 ERROR unit.failover/1.juju-log peer-cluster:10: [Errno 111] Connection refused
unit-opensearch-0: 02:48:23 ERROR unit.opensearch/0.juju-log peer-cluster:11: [Errno 111] Connection refused
unit-opensearch-0: 02:48:24 ERROR unit.opensearch/0.juju-log peer-cluster:11: [Errno 111] Connection refused
unit-opensearch-0: 02:48:24 ERROR unit.opensearch/0.juju-log peer-cluster:11: [Errno 111] Connection refused
unit-opensearch-0: 02:48:25 ERROR unit.opensearch/0.juju-log [Errno 111] Connection refused
unit-opensearch-0: 02:48:26 ERROR unit.opensearch/0.juju-log opensearch-peers:9: [Errno 111] Connection refused
unit-opensearch-0: 02:48:27 ERROR unit.opensearch/0.juju-log opensearch-peers:9: [Errno 111] Connection refused
unit-opensearch-0: 02:48:27 ERROR unit.opensearch/0.juju-log opensearch-peers:9: Cannot connect to the OpenSearch server...
unit-opensearch-0: 02:48:27 ERROR unit.opensearch/0.juju-log opensearch-peers:9: [Errno 111] Connection refused
unit-opensearch-0: 02:48:27 ERROR unit.opensearch/0.juju-log opensearch-peers:9: [Errno 111] Connection refused
unit-opensearch-0: 02:48:27 ERROR unit.opensearch/0.juju-log opensearch-peers:9: [Errno 111] Connection refused
unit-opensearch-0: 02:48:27 ERROR unit.opensearch/0.juju-log opensearch-peers:9: [Errno 111] Connection refused
unit-opensearch-0: 02:48:28 ERROR unit.opensearch/0.juju-log opensearch-peers:9: [Errno 111] Connection refused
unit-opensearch-0: 02:48:28 ERROR unit.opensearch/0.juju-log opensearch-peers:9: [Errno 111] Connection refused
unit-opensearch-0: 02:48:28 ERROR unit.opensearch/0.juju-log opensearch-peers:9: [Errno 111] Connection refused
unit-opensearch-0: 02:48:29 ERROR unit.opensearch/0.juju-log opensearch-peers:9: [Errno 111] Connection refused
unit-opensearch-0: 02:48:29 ERROR unit.opensearch/0.juju-log opensearch-peers:9: Cannot connect to the OpenSearch server...
unit-opensearch-0: 02:48:29 ERROR unit.opensearch/0.juju-log opensearch-peers:9: [Errno 111] Connection refused
unit-opensearch-0: 02:48:32 ERROR unit.opensearch/0.juju-log opensearch-peers:9: [Errno 111] Connection refused
unit-opensearch-0: 02:48:35 ERROR unit.opensearch/0.juju-log opensearch-peers:9: [Errno 111] Connection refused
unit-opensearch-0: 02:48:38 ERROR unit.opensearch/0.juju-log opensearch-peers:9: [Errno 111] Connection refused
unit-opensearch-0: 02:48:41 ERROR unit.opensearch/0.juju-log opensearch-peers:9: [Errno 111] Connection refused
unit-opensearch-0: 02:48:44 ERROR unit.opensearch/0.juju-log opensearch-peers:9: [Errno 111] Connection refused
unit-failover-1: 02:49:28 ERROR unit.failover/1.juju-log node-lock-fallback:2: [Errno 111] Connection refused
unit-failover-1: 02:49:29 ERROR unit.failover/1.juju-log upgrade-version-a:3: [Errno 111] Connection refused
unit-failover-1: 02:49:30 ERROR unit.failover/1.juju-log upgrade-version-a:3: [Errno 111] Connection refused
unit-failover-1: 02:49:31 ERROR unit.failover/1.juju-log node-lock-fallback:2: [Errno 111] Connection refused
unit-failover-1: 02:49:31 ERROR unit.failover/1.juju-log opensearch-peers:1: [Errno 111] Connection refused
unit-failover-1: 02:49:32 ERROR unit.failover/1.juju-log opensearch-peers:1: [Errno 111] Connection refused
unit-failover-1: 02:49:32 ERROR unit.failover/1.juju-log opensearch-peers:1: [Errno 111] Connection refused
unit-failover-1: 02:49:32 ERROR unit.failover/1.juju-log opensearch-peers:1: [Errno 111] Connection refused
unit-failover-1: 02:49:32 ERROR unit.failover/1.juju-log opensearch-peers:1: [Errno 111] Connection refused
unit-failover-1: 02:49:32 ERROR unit.failover/1.juju-log opensearch-peers:1: [Errno 111] Connection refused
unit-failover-1: 02:49:32 ERROR unit.failover/1.juju-log opensearch-peers:1: [Errno 111] Connection refused
unit-failover-1: 02:49:32 ERROR unit.failover/1.juju-log opensearch-peers:1: [Errno 111] Connection refused
unit-failover-1: 02:49:33 ERROR unit.failover/1.juju-log upgrade-version-a:3: [Errno 111] Connection refused
unit-failover-1: 02:49:34 ERROR unit.failover/1.juju-log upgrade-version-a:3: [Errno 111] Connection refused
unit-failover-1: 02:49:36 ERROR unit.failover/1.juju-log opensearch-peers:1: [Errno 111] Connection refused
unit-failover-1: 02:49:36 ERROR unit.failover/1.juju-log opensearch-peers:1: [Errno 111] Connection refused
unit-failover-1: 02:49:36 ERROR unit.failover/1.juju-log opensearch-peers:1: [Errno 111] Connection refused
unit-failover-0: 02:49:37 ERROR unit.failover/0.juju-log [Errno 111] Connection refused
unit-failover-0: 02:49:38 ERROR unit.failover/0.juju-log certificates:14: [Errno 111] Connection refused
unit-failover-1: 02:49:38 ERROR unit.failover/1.juju-log opensearch-peers:1: [Errno 111] Connection refused
unit-failover-1: 02:49:38 ERROR unit.failover/1.juju-log opensearch-peers:1: [Errno 111] Connection refused
unit-failover-1: 02:49:38 ERROR unit.failover/1.juju-log opensearch-peers:1: [Errno 111] Connection refused
unit-failover-0: 02:49:39 ERROR unit.failover/0.juju-log certificates:14: [Errno 111] Connection refused
unit-failover-1: 02:49:39 ERROR unit.failover/1.juju-log certificates:14: [Errno 111] Connection refused
unit-failover-0: 02:49:39 ERROR unit.failover/0.juju-log peer-cluster-orchestrator:12: [Errno 111] Connection refused
unit-failover-0: 02:49:40 ERROR unit.failover/0.juju-log certificates:14: [Errno 111] Connection refused
unit-failover-1: 02:49:42 ERROR unit.failover/1.juju-log [Errno 111] Connection refused
unit-failover-1: 02:49:43 ERROR unit.failover/1.juju-log [Errno 111] Connection refused
unit-failover-0: 02:49:44 ERROR unit.failover/0.juju-log [Errno 111] Connection refused
unit-failover-1: 02:49:44 ERROR unit.failover/1.juju-log opensearch-peers:1: [Errno 111] Connection refused
unit-failover-1: 02:49:44 ERROR unit.failover/1.juju-log opensearch-peers:1: [Errno 111] Connection refused
unit-failover-1: 02:49:44 ERROR unit.failover/1.juju-log opensearch-peers:1: [Errno 111] Connection refused
unit-failover-1: 02:49:44 ERROR unit.failover/1.juju-log opensearch-peers:1: [Errno 111] Connection refused
unit-failover-1: 02:49:44 ERROR unit.failover/1.juju-log opensearch-peers:1: [Errno 111] Connection refused
unit-failover-1: 02:49:44 ERROR unit.failover/1.juju-log opensearch-peers:1: [Errno 111] Connection refused
unit-failover-1: 02:49:44 ERROR unit.failover/1.juju-log opensearch-peers:1: [Errno 111] Connection refused
unit-failover-0: 02:49:45 ERROR unit.failover/0.juju-log [Errno 111] Connection refused
unit-failover-1: 02:49:45 ERROR unit.failover/1.juju-log [Errno 111] Connection refused
unit-failover-0: 02:49:45 ERROR unit.failover/0.juju-log peer-cluster:10: [Errno 111] Connection refused
unit-failover-0: 02:49:46 ERROR unit.failover/0.juju-log peer-cluster:10: [Errno 111] Connection refused
unit-failover-1: 02:49:46 ERROR unit.failover/1.juju-log [Errno 111] Connection refused
unit-failover-0: 02:49:46 ERROR unit.failover/0.juju-log peer-cluster:10: [Errno 111] Connection refused
unit-failover-1: 02:49:47 ERROR unit.failover/1.juju-log certificates:14: [Errno 111] Connection refused
unit-failover-0: 02:49:47 ERROR unit.failover/0.juju-log peer-cluster:10: [Errno 111] Connection refused
unit-failover-0: 02:49:48 ERROR unit.failover/0.juju-log [Errno 111] Connection refused
unit-failover-1: 02:49:48 ERROR unit.failover/1.juju-log [Errno 111] Connection refused
unit-failover-1: 02:49:48 ERROR unit.failover/1.juju-log [Errno 111] Connection refused
unit-failover-0: 02:49:49 ERROR unit.failover/0.juju-log [Errno 111] Connection refused
unit-failover-1: 02:49:49 ERROR unit.failover/1.juju-log [Errno 111] Connection refused
unit-failover-1: 02:49:49 ERROR unit.failover/1.juju-log [Errno 111] Connection refused
unit-failover-0: 02:49:50 ERROR unit.failover/0.juju-log [Errno 111] Connection refused
unit-failover-0: 02:49:50 ERROR unit.failover/0.juju-log Cannot connect to the OpenSearch server...
unit-failover-0: 02:49:50 ERROR unit.failover/0.juju-log [Errno 111] Connection refused
unit-failover-0: 02:49:50 ERROR unit.failover/0.juju-log [Errno 111] Connection refused
unit-failover-0: 02:49:50 ERROR unit.failover/0.juju-log [Errno 111] Connection refused
unit-failover-0: 02:49:50 ERROR unit.failover/0.juju-log [Errno 111] Connection refused
unit-failover-0: 02:49:50 ERROR unit.failover/0.juju-log [Errno 111] Connection refused
unit-failover-1: 02:49:50 ERROR unit.failover/1.juju-log [Errno 111] Connection refused
unit-failover-0: 02:49:50 ERROR unit.failover/0.juju-log [Errno 111] Connection refused
unit-failover-1: 02:49:50 ERROR unit.failover/1.juju-log [Errno 111] Connection refused
unit-failover-0: 02:49:50 ERROR unit.failover/0.juju-log [Errno 111] Connection refused
unit-failover-1: 02:49:51 ERROR unit.failover/1.juju-log [Errno 111] Connection refused
unit-failover-1: 02:49:51 ERROR unit.failover/1.juju-log Cannot connect to the OpenSearch server...
unit-failover-1: 02:49:51 ERROR unit.failover/1.juju-log [Errno 111] Connection refused
unit-failover-1: 02:49:51 ERROR unit.failover/1.juju-log [Errno 111] Connection refused
unit-failover-1: 02:49:51 ERROR unit.failover/1.juju-log [Errno 111] Connection refused
unit-failover-1: 02:49:51 ERROR unit.failover/1.juju-log [Errno 111] Connection refused
unit-failover-0: 02:49:51 ERROR unit.failover/0.juju-log [Errno 111] Connection refused
unit-failover-0: 02:49:51 ERROR unit.failover/0.juju-log Cannot connect to the OpenSearch server...
unit-failover-0: 02:49:52 ERROR unit.failover/0.juju-log [Errno 111] Connection refused
unit-failover-1: 02:49:52 ERROR unit.failover/1.juju-log [Errno 111] Connection refused
unit-failover-1: 02:49:52 ERROR unit.failover/1.juju-log Cannot connect to the OpenSearch server...
unit-failover-1: 02:49:52 ERROR unit.failover/1.juju-log [Errno 111] Connection refused
unit-failover-1: 02:49:52 ERROR unit.failover/1.juju-log [Errno 111] Connection refused
unit-failover-1: 02:49:53 ERROR unit.failover/1.juju-log [Errno 111] Connection refused
unit-failover-1: 02:49:53 ERROR unit.failover/1.juju-log [Errno 111] Connection refused
unit-failover-1: 02:49:54 ERROR unit.failover/1.juju-log [Errno 111] Connection refused
unit-failover-1: 02:49:54 ERROR unit.failover/1.juju-log Cannot connect to the OpenSearch server...
unit-failover-1: 02:49:54 ERROR unit.failover/1.juju-log [Errno 111] Connection refused
unit-failover-1: 02:49:54 ERROR unit.failover/1.juju-log [Errno 111] Connection refused
unit-failover-1: 02:49:54 ERROR unit.failover/1.juju-log [Errno 111] Connection refused
unit-failover-1: 02:49:54 ERROR unit.failover/1.juju-log [Errno 111] Connection refused
unit-failover-0: 02:49:55 ERROR unit.failover/0.juju-log [Errno 111] Connection refused
unit-failover-1: 02:49:55 ERROR unit.failover/1.juju-log peer-cluster:10: [Errno 111] Connection refused
unit-failover-1: 02:49:55 ERROR unit.failover/1.juju-log peer-cluster:10: Cannot connect to the OpenSearch server...
unit-failover-1: 02:49:55 ERROR unit.failover/1.juju-log peer-cluster:10: [Errno 111] Connection refused
unit-failover-1: 02:49:55 ERROR unit.failover/1.juju-log peer-cluster:10: [Errno 111] Connection refused
unit-failover-1: 02:49:55 ERROR unit.failover/1.juju-log peer-cluster:10: [Errno 111] Connection refused
unit-failover-1: 02:49:55 ERROR unit.failover/1.juju-log peer-cluster:10: [Errno 111] Connection refused
unit-failover-1: 02:49:56 ERROR unit.failover/1.juju-log opensearch-peers:1: [Errno 111] Connection refused
unit-failover-1: 02:49:56 ERROR unit.failover/1.juju-log opensearch-peers:1: Cannot connect to the OpenSearch server...
unit-failover-1: 02:49:56 ERROR unit.failover/1.juju-log opensearch-peers:1: [Errno 111] Connection refused
unit-failover-1: 02:49:56 ERROR unit.failover/1.juju-log opensearch-peers:1: [Errno 111] Connection refused
unit-failover-1: 02:49:56 ERROR unit.failover/1.juju-log opensearch-peers:1: [Errno 111] Connection refused
unit-failover-1: 02:49:56 ERROR unit.failover/1.juju-log opensearch-peers:1: [Errno 111] Connection refused
unit-failover-1: 02:49:57 ERROR unit.failover/1.juju-log opensearch-peers:1: [Errno 111] Connection refused
unit-failover-1: 02:49:57 ERROR unit.failover/1.juju-log opensearch-peers:1: [Errno 111] Connection refused
unit-failover-0: 02:49:58 ERROR unit.failover/0.juju-log [Errno 111] Connection refused
unit-failover-0: 02:50:01 ERROR unit.failover/0.juju-log [Errno 111] Connection refused
unit-failover-0: 02:50:04 ERROR unit.failover/0.juju-log [Errno 111] Connection refused
unit-failover-1: 02:50:08 ERROR unit.failover/1.juju-log opensearch-peers:1: [Errno 111] Connection refused
unit-failover-1: 02:50:08 ERROR unit.failover/1.juju-log opensearch-peers:1: Cannot connect to the OpenSearch server...
unit-failover-1: 02:50:08 ERROR unit.failover/1.juju-log opensearch-peers:1: [Errno 111] Connection refused
unit-failover-1: 02:50:08 ERROR unit.failover/1.juju-log opensearch-peers:1: [Errno 111] Connection refused
unit-failover-1: 02:50:08 ERROR unit.failover/1.juju-log opensearch-peers:1: [Errno 111] Connection refused
unit-failover-1: 02:50:10 ERROR unit.failover/1.juju-log opensearch-peers:1: [Errno 111] Connection refused
unit-failover-1: 02:50:10 ERROR unit.failover/1.juju-log opensearch-peers:1: Cannot connect to the OpenSearch server...
unit-failover-1: 02:50:10 ERROR unit.failover/1.juju-log opensearch-peers:1: [Errno 111] Connection refused
unit-failover-1: 02:50:10 ERROR unit.failover/1.juju-log opensearch-peers:1: [Errno 111] Connection refused
unit-failover-1: 02:50:10 ERROR unit.failover/1.juju-log opensearch-peers:1: [Errno 111] Connection refused
unit-failover-1: 02:50:10 ERROR unit.failover/1.juju-log opensearch-peers:1: [Errno 111] Connection refused
unit-failover-1: 02:50:10 ERROR unit.failover/1.juju-log opensearch-peers:1: [Errno 111] Connection refused
unit-failover-1: 02:50:10 ERROR unit.failover/1.juju-log opensearch-peers:1: [Errno 111] Connection refused
unit-failover-1: 02:50:11 ERROR unit.failover/1.juju-log opensearch-peers:1: [Errno 111] Connection refused
unit-failover-1: 02:50:11 ERROR unit.failover/1.juju-log opensearch-peers:1: [Errno 111] Connection refused
unit-failover-1: 02:50:11 ERROR unit.failover/1.juju-log opensearch-peers:1: Cannot connect to the OpenSearch server...
unit-failover-1: 02:50:12 ERROR unit.failover/1.juju-log opensearch-peers:1: [Errno 111] Connection refused
unit-failover-1: 02:50:15 ERROR unit.failover/1.juju-log opensearch-peers:1: [Errno 111] Connection refused
unit-failover-0: 02:50:16 ERROR unit.failover/0.juju-log certificates:14: err: Mac verify error: invalid password?
 / out: 
unit-failover-0: 02:50:16 ERROR unit.failover/0.juju-log certificates:14: Uncaught exception while in charm code:
Traceback (most recent call last):
  File "/var/lib/juju/agents/unit-failover-0/charm/./src/charm.py", line 213, in <module>
    main(OpenSearchOperatorCharm)
  File "/var/lib/juju/agents/unit-failover-0/charm/venv/ops/main.py", line 551, in main
    manager.run()
  File "/var/lib/juju/agents/unit-failover-0/charm/venv/ops/main.py", line 530, in run
    self._emit()
  File "/var/lib/juju/agents/unit-failover-0/charm/venv/ops/main.py", line 519, in _emit
    _emit_charm_event(self.charm, self.dispatcher.event_name)
  File "/var/lib/juju/agents/unit-failover-0/charm/venv/ops/main.py", line 147, in _emit_charm_event
    event_to_emit.emit(*args, **kwargs)
  File "/var/lib/juju/agents/unit-failover-0/charm/venv/ops/framework.py", line 348, in emit
    framework._emit(event)
  File "/var/lib/juju/agents/unit-failover-0/charm/venv/ops/framework.py", line 860, in _emit
    self._reemit(event_path)
  File "/var/lib/juju/agents/unit-failover-0/charm/venv/ops/framework.py", line 950, in _reemit
    custom_handler(event)
  File "/var/lib/juju/agents/unit-failover-0/charm/lib/charms/tls_certificates_interface/v3/tls_certificates.py", line 1911, in _on_relation_changed
    self.on.certificate_available.emit(
  File "/var/lib/juju/agents/unit-failover-0/charm/venv/ops/framework.py", line 348, in emit
    framework._emit(event)
  File "/var/lib/juju/agents/unit-failover-0/charm/venv/ops/framework.py", line 860, in _emit
    self._reemit(event_path)
  File "/var/lib/juju/agents/unit-failover-0/charm/venv/ops/framework.py", line 950, in _reemit
    custom_handler(event)
  File "/var/lib/juju/agents/unit-failover-0/charm/lib/charms/opensearch/v0/opensearch_tls.py", line 210, in _on_certificate_available
    if self._read_stored_ca() is None:
  File "/var/lib/juju/agents/unit-failover-0/charm/lib/charms/opensearch/v0/opensearch_tls.py", line 492, in _read_stored_ca
    stored_certs = run_cmd(
  File "/var/lib/juju/agents/unit-failover-0/charm/lib/charms/opensearch/v0/helper_charm.py", line 194, in run_cmd
    raise OpenSearchCmdError(cmd=command, out=output.stdout, err=output.stderr)
charms.opensearch.v0.opensearch_exceptions.OpenSearchCmdError
unit-failover-0: 02:50:16 ERROR juju.worker.uniter.operation hook "certificates-relation-changed" (via hook dispatching script: dispatch) failed: exit status 1
unit-failover-1: 02:50:18 ERROR unit.failover/1.juju-log opensearch-peers:1: [Errno 111] Connection refused
unit-failover-1: 02:50:21 ERROR unit.failover/1.juju-log opensearch-peers:1: [Errno 111] Connection refused
unit-failover-0: 02:50:22 ERROR unit.failover/0.juju-log certificates:14: err: Mac verify error: invalid password?
 / out: 
unit-failover-0: 02:50:22 ERROR unit.failover/0.juju-log certificates:14: Uncaught exception while in charm code:
Traceback (most recent call last):
  File "/var/lib/juju/agents/unit-failover-0/charm/./src/charm.py", line 213, in <module>
    main(OpenSearchOperatorCharm)
  File "/var/lib/juju/agents/unit-failover-0/charm/venv/ops/main.py", line 551, in main
    manager.run()
  File "/var/lib/juju/agents/unit-failover-0/charm/venv/ops/main.py", line 530, in run
    self._emit()
  File "/var/lib/juju/agents/unit-failover-0/charm/venv/ops/main.py", line 519, in _emit
    _emit_charm_event(self.charm, self.dispatcher.event_name)
  File "/var/lib/juju/agents/unit-failover-0/charm/venv/ops/main.py", line 147, in _emit_charm_event
    event_to_emit.emit(*args, **kwargs)
  File "/var/lib/juju/agents/unit-failover-0/charm/venv/ops/framework.py", line 348, in emit
    framework._emit(event)
  File "/var/lib/juju/agents/unit-failover-0/charm/venv/ops/framework.py", line 860, in _emit
    self._reemit(event_path)
  File "/var/lib/juju/agents/unit-failover-0/charm/venv/ops/framework.py", line 950, in _reemit
    custom_handler(event)
  File "/var/lib/juju/agents/unit-failover-0/charm/lib/charms/tls_certificates_interface/v3/tls_certificates.py", line 1911, in _on_relation_changed
    self.on.certificate_available.emit(
  File "/var/lib/juju/agents/unit-failover-0/charm/venv/ops/framework.py", line 348, in emit
    framework._emit(event)
  File "/var/lib/juju/agents/unit-failover-0/charm/venv/ops/framework.py", line 860, in _emit
    self._reemit(event_path)
  File "/var/lib/juju/agents/unit-failover-0/charm/venv/ops/framework.py", line 950, in _reemit
    custom_handler(event)
  File "/var/lib/juju/agents/unit-failover-0/charm/lib/charms/opensearch/v0/opensearch_tls.py", line 210, in _on_certificate_available
    if self._read_stored_ca() is None:
  File "/var/lib/juju/agents/unit-failover-0/charm/lib/charms/opensearch/v0/opensearch_tls.py", line 492, in _read_stored_ca
    stored_certs = run_cmd(
  File "/var/lib/juju/agents/unit-failover-0/charm/lib/charms/opensearch/v0/helper_charm.py", line 194, in run_cmd
    raise OpenSearchCmdError(cmd=command, out=output.stdout, err=output.stderr)
charms.opensearch.v0.opensearch_exceptions.OpenSearchCmdError
unit-failover-0: 02:50:22 ERROR juju.worker.uniter.operation hook "certificates-relation-changed" (via hook dispatching script: dispatch) failed: exit status 1
unit-failover-1: 02:50:24 ERROR unit.failover/1.juju-log opensearch-peers:1: [Errno 111] Connection refused
unit-failover-0: 02:50:33 ERROR unit.failover/0.juju-log certificates:14: err: Mac verify error: invalid password?
 / out: 
unit-failover-0: 02:50:33 ERROR unit.failover/0.juju-log certificates:14: Uncaught exception while in charm code:
Traceback (most recent call last):
  File "/var/lib/juju/agents/unit-failover-0/charm/./src/charm.py", line 213, in <module>
    main(OpenSearchOperatorCharm)
  File "/var/lib/juju/agents/unit-failover-0/charm/venv/ops/main.py", line 551, in main
    manager.run()
  File "/var/lib/juju/agents/unit-failover-0/charm/venv/ops/main.py", line 530, in run
    self._emit()
  File "/var/lib/juju/agents/unit-failover-0/charm/venv/ops/main.py", line 519, in _emit
    _emit_charm_event(self.charm, self.dispatcher.event_name)
  File "/var/lib/juju/agents/unit-failover-0/charm/venv/ops/main.py", line 147, in _emit_charm_event
    event_to_emit.emit(*args, **kwargs)
  File "/var/lib/juju/agents/unit-failover-0/charm/venv/ops/framework.py", line 348, in emit
    framework._emit(event)
  File "/var/lib/juju/agents/unit-failover-0/charm/venv/ops/framework.py", line 860, in _emit
    self._reemit(event_path)
  File "/var/lib/juju/agents/unit-failover-0/charm/venv/ops/framework.py", line 950, in _reemit
    custom_handler(event)
  File "/var/lib/juju/agents/unit-failover-0/charm/lib/charms/tls_certificates_interface/v3/tls_certificates.py", line 1911, in _on_relation_changed
    self.on.certificate_available.emit(
  File "/var/lib/juju/agents/unit-failover-0/charm/venv/ops/framework.py", line 348, in emit
    framework._emit(event)
  File "/var/lib/juju/agents/unit-failover-0/charm/venv/ops/framework.py", line 860, in _emit
    self._reemit(event_path)
  File "/var/lib/juju/agents/unit-failover-0/charm/venv/ops/framework.py", line 950, in _reemit
    custom_handler(event)
  File "/var/lib/juju/agents/unit-failover-0/charm/lib/charms/opensearch/v0/opensearch_tls.py", line 210, in _on_certificate_available
    if self._read_stored_ca() is None:
  File "/var/lib/juju/agents/unit-failover-0/charm/lib/charms/opensearch/v0/opensearch_tls.py", line 492, in _read_stored_ca
    stored_certs = run_cmd(
  File "/var/lib/juju/agents/unit-failover-0/charm/lib/charms/opensearch/v0/helper_charm.py", line 194, in run_cmd
    raise OpenSearchCmdError(cmd=command, out=output.stdout, err=output.stderr)
charms.opensearch.v0.opensearch_exceptions.OpenSearchCmdError
unit-failover-0: 02:50:33 ERROR juju.worker.uniter.operation hook "certificates-relation-changed" (via hook dispatching script: dispatch) failed: exit status 1
unit-failover-0: 02:50:54 ERROR unit.failover/0.juju-log certificates:14: err: Mac verify error: invalid password?
 / out: 
unit-failover-0: 02:50:54 ERROR unit.failover/0.juju-log certificates:14: Uncaught exception while in charm code:
Traceback (most recent call last):
  File "/var/lib/juju/agents/unit-failover-0/charm/./src/charm.py", line 213, in <module>
    main(OpenSearchOperatorCharm)
  File "/var/lib/juju/agents/unit-failover-0/charm/venv/ops/main.py", line 551, in main
    manager.run()
  File "/var/lib/juju/agents/unit-failover-0/charm/venv/ops/main.py", line 530, in run
    self._emit()
  File "/var/lib/juju/agents/unit-failover-0/charm/venv/ops/main.py", line 519, in _emit
    _emit_charm_event(self.charm, self.dispatcher.event_name)
  File "/var/lib/juju/agents/unit-failover-0/charm/venv/ops/main.py", line 147, in _emit_charm_event
    event_to_emit.emit(*args, **kwargs)
  File "/var/lib/juju/agents/unit-failover-0/charm/venv/ops/framework.py", line 348, in emit
    framework._emit(event)
  File "/var/lib/juju/agents/unit-failover-0/charm/venv/ops/framework.py", line 860, in _emit
    self._reemit(event_path)
  File "/var/lib/juju/agents/unit-failover-0/charm/venv/ops/framework.py", line 950, in _reemit
    custom_handler(event)
  File "/var/lib/juju/agents/unit-failover-0/charm/lib/charms/tls_certificates_interface/v3/tls_certificates.py", line 1911, in _on_relation_changed
    self.on.certificate_available.emit(
  File "/var/lib/juju/agents/unit-failover-0/charm/venv/ops/framework.py", line 348, in emit
    framework._emit(event)
  File "/var/lib/juju/agents/unit-failover-0/charm/venv/ops/framework.py", line 860, in _emit
    self._reemit(event_path)
  File "/var/lib/juju/agents/unit-failover-0/charm/venv/ops/framework.py", line 950, in _reemit
    custom_handler(event)
  File "/var/lib/juju/agents/unit-failover-0/charm/lib/charms/opensearch/v0/opensearch_tls.py", line 210, in _on_certificate_available
    if self._read_stored_ca() is None:
  File "/var/lib/juju/agents/unit-failover-0/charm/lib/charms/opensearch/v0/opensearch_tls.py", line 492, in _read_stored_ca
    stored_certs = run_cmd(
  File "/var/lib/juju/agents/unit-failover-0/charm/lib/charms/opensearch/v0/helper_charm.py", line 194, in run_cmd
    raise OpenSearchCmdError(cmd=command, out=output.stdout, err=output.stderr)
charms.opensearch.v0.opensearch_exceptions.OpenSearchCmdError
unit-failover-0: 02:50:54 ERROR juju.worker.uniter.operation hook "certificates-relation-changed" (via hook dispatching script: dispatch) failed: exit status 1
unit-failover-0: 02:51:36 ERROR unit.failover/0.juju-log certificates:14: err: Mac verify error: invalid password?
 / out: 
unit-failover-0: 02:51:36 ERROR unit.failover/0.juju-log certificates:14: Uncaught exception while in charm code:
Traceback (most recent call last):
  File "/var/lib/juju/agents/unit-failover-0/charm/./src/charm.py", line 213, in <module>
    main(OpenSearchOperatorCharm)
  File "/var/lib/juju/agents/unit-failover-0/charm/venv/ops/main.py", line 551, in main
    manager.run()
  File "/var/lib/juju/agents/unit-failover-0/charm/venv/ops/main.py", line 530, in run
    self._emit()
  File "/var/lib/juju/agents/unit-failover-0/charm/venv/ops/main.py", line 519, in _emit
    _emit_charm_event(self.charm, self.dispatcher.event_name)
  File "/var/lib/juju/agents/unit-failover-0/charm/venv/ops/main.py", line 147, in _emit_charm_event
    event_to_emit.emit(*args, **kwargs)
  File "/var/lib/juju/agents/unit-failover-0/charm/venv/ops/framework.py", line 348, in emit
    framework._emit(event)
  File "/var/lib/juju/agents/unit-failover-0/charm/venv/ops/framework.py", line 860, in _emit
    self._reemit(event_path)
  File "/var/lib/juju/agents/unit-failover-0/charm/venv/ops/framework.py", line 950, in _reemit
    custom_handler(event)
  File "/var/lib/juju/agents/unit-failover-0/charm/lib/charms/tls_certificates_interface/v3/tls_certificates.py", line 1911, in _on_relation_changed
    self.on.certificate_available.emit(
  File "/var/lib/juju/agents/unit-failover-0/charm/venv/ops/framework.py", line 348, in emit
    framework._emit(event)
  File "/var/lib/juju/agents/unit-failover-0/charm/venv/ops/framework.py", line 860, in _emit
    self._reemit(event_path)
  File "/var/lib/juju/agents/unit-failover-0/charm/venv/ops/framework.py", line 950, in _reemit
    custom_handler(event)
  File "/var/lib/juju/agents/unit-failover-0/charm/lib/charms/opensearch/v0/opensearch_tls.py", line 210, in _on_certificate_available
    if self._read_stored_ca() is None:
  File "/var/lib/juju/agents/unit-failover-0/charm/lib/charms/opensearch/v0/opensearch_tls.py", line 492, in _read_stored_ca
    stored_certs = run_cmd(
  File "/var/lib/juju/agents/unit-failover-0/charm/lib/charms/opensearch/v0/helper_charm.py", line 194, in run_cmd
    raise OpenSearchCmdError(cmd=command, out=output.stdout, err=output.stderr)
charms.opensearch.v0.opensearch_exceptions.OpenSearchCmdError
unit-failover-0: 02:51:36 ERROR juju.worker.uniter.operation hook "certificates-relation-changed" (via hook dispatching script: dispatch) failed: exit status 1
unit-failover-0: 02:53:00 ERROR unit.failover/0.juju-log certificates:14: err: Mac verify error: invalid password?
 / out: 
unit-failover-0: 02:53:00 ERROR unit.failover/0.juju-log certificates:14: Uncaught exception while in charm code:
Traceback (most recent call last):
  File "/var/lib/juju/agents/unit-failover-0/charm/./src/charm.py", line 213, in <module>
    main(OpenSearchOperatorCharm)
  File "/var/lib/juju/agents/unit-failover-0/charm/venv/ops/main.py", line 551, in main
    manager.run()
  File "/var/lib/juju/agents/unit-failover-0/charm/venv/ops/main.py", line 530, in run
    self._emit()
  File "/var/lib/juju/agents/unit-failover-0/charm/venv/ops/main.py", line 519, in _emit
    _emit_charm_event(self.charm, self.dispatcher.event_name)
  File "/var/lib/juju/agents/unit-failover-0/charm/venv/ops/main.py", line 147, in _emit_charm_event
    event_to_emit.emit(*args, **kwargs)
  File "/var/lib/juju/agents/unit-failover-0/charm/venv/ops/framework.py", line 348, in emit
    framework._emit(event)
  File "/var/lib/juju/agents/unit-failover-0/charm/venv/ops/framework.py", line 860, in _emit
    self._reemit(event_path)
  File "/var/lib/juju/agents/unit-failover-0/charm/venv/ops/framework.py", line 950, in _reemit
    custom_handler(event)
  File "/var/lib/juju/agents/unit-failover-0/charm/lib/charms/tls_certificates_interface/v3/tls_certificates.py", line 1911, in _on_relation_changed
    self.on.certificate_available.emit(
  File "/var/lib/juju/agents/unit-failover-0/charm/venv/ops/framework.py", line 348, in emit
    framework._emit(event)
  File "/var/lib/juju/agents/unit-failover-0/charm/venv/ops/framework.py", line 860, in _emit
    self._reemit(event_path)
  File "/var/lib/juju/agents/unit-failover-0/charm/venv/ops/framework.py", line 950, in _reemit
    custom_handler(event)
  File "/var/lib/juju/agents/unit-failover-0/charm/lib/charms/opensearch/v0/opensearch_tls.py", line 210, in _on_certificate_available
    if self._read_stored_ca() is None:
  File "/var/lib/juju/agents/unit-failover-0/charm/lib/charms/opensearch/v0/opensearch_tls.py", line 492, in _read_stored_ca
    stored_certs = run_cmd(
  File "/var/lib/juju/agents/unit-failover-0/charm/lib/charms/opensearch/v0/helper_charm.py", line 194, in run_cmd
    raise OpenSearchCmdError(cmd=command, out=output.stdout, err=output.stderr)
charms.opensearch.v0.opensearch_exceptions.OpenSearchCmdError
unit-failover-0: 02:53:00 ERROR juju.worker.uniter.operation hook "certificates-relation-changed" (via hook dispatching script: dispatch) failed: exit status 1
unit-failover-0: 02:55:49 ERROR unit.failover/0.juju-log certificates:14: err: Mac verify error: invalid password?
 / out: 
unit-failover-0: 02:55:49 ERROR unit.failover/0.juju-log certificates:14: Uncaught exception while in charm code:
Traceback (most recent call last):
  File "/var/lib/juju/agents/unit-failover-0/charm/./src/charm.py", line 213, in <module>
    main(OpenSearchOperatorCharm)
  File "/var/lib/juju/agents/unit-failover-0/charm/venv/ops/main.py", line 551, in main
    manager.run()
  File "/var/lib/juju/agents/unit-failover-0/charm/venv/ops/main.py", line 530, in run
    self._emit()
  File "/var/lib/juju/agents/unit-failover-0/charm/venv/ops/main.py", line 519, in _emit
    _emit_charm_event(self.charm, self.dispatcher.event_name)
  File "/var/lib/juju/agents/unit-failover-0/charm/venv/ops/main.py", line 147, in _emit_charm_event
    event_to_emit.emit(*args, **kwargs)
  File "/var/lib/juju/agents/unit-failover-0/charm/venv/ops/framework.py", line 348, in emit
    framework._emit(event)
  File "/var/lib/juju/agents/unit-failover-0/charm/venv/ops/framework.py", line 860, in _emit
    self._reemit(event_path)
  File "/var/lib/juju/agents/unit-failover-0/charm/venv/ops/framework.py", line 950, in _reemit
    custom_handler(event)
  File "/var/lib/juju/agents/unit-failover-0/charm/lib/charms/tls_certificates_interface/v3/tls_certificates.py", line 1911, in _on_relation_changed
    self.on.certificate_available.emit(
  File "/var/lib/juju/agents/unit-failover-0/charm/venv/ops/framework.py", line 348, in emit
    framework._emit(event)
  File "/var/lib/juju/agents/unit-failover-0/charm/venv/ops/framework.py", line 860, in _emit
    self._reemit(event_path)
  File "/var/lib/juju/agents/unit-failover-0/charm/venv/ops/framework.py", line 950, in _reemit
    custom_handler(event)
  File "/var/lib/juju/agents/unit-failover-0/charm/lib/charms/opensearch/v0/opensearch_tls.py", line 210, in _on_certificate_available
    if self._read_stored_ca() is None:
  File "/var/lib/juju/agents/unit-failover-0/charm/lib/charms/opensearch/v0/opensearch_tls.py", line 492, in _read_stored_ca
    stored_certs = run_cmd(
  File "/var/lib/juju/agents/unit-failover-0/charm/lib/charms/opensearch/v0/helper_charm.py", line 194, in run_cmd
    raise OpenSearchCmdError(cmd=command, out=output.stdout, err=output.stderr)
charms.opensearch.v0.opensearch_exceptions.OpenSearchCmdError
unit-failover-0: 02:55:50 ERROR juju.worker.uniter.operation hook "certificates-relation-changed" (via hook dispatching script: dispatch) failed: exit status 1
unit-failover-0: 03:00:50 ERROR unit.failover/0.juju-log certificates:14: err: Mac verify error: invalid password?
 / out: 
unit-failover-0: 03:00:50 ERROR unit.failover/0.juju-log certificates:14: Uncaught exception while in charm code:
Traceback (most recent call last):
  File "/var/lib/juju/agents/unit-failover-0/charm/./src/charm.py", line 213, in <module>
    main(OpenSearchOperatorCharm)
  File "/var/lib/juju/agents/unit-failover-0/charm/venv/ops/main.py", line 551, in main
    manager.run()
  File "/var/lib/juju/agents/unit-failover-0/charm/venv/ops/main.py", line 530, in run
    self._emit()
  File "/var/lib/juju/agents/unit-failover-0/charm/venv/ops/main.py", line 519, in _emit
    _emit_charm_event(self.charm, self.dispatcher.event_name)
  File "/var/lib/juju/agents/unit-failover-0/charm/venv/ops/main.py", line 147, in _emit_charm_event
    event_to_emit.emit(*args, **kwargs)
  File "/var/lib/juju/agents/unit-failover-0/charm/venv/ops/framework.py", line 348, in emit
    framework._emit(event)
  File "/var/lib/juju/agents/unit-failover-0/charm/venv/ops/framework.py", line 860, in _emit
    self._reemit(event_path)
  File "/var/lib/juju/agents/unit-failover-0/charm/venv/ops/framework.py", line 950, in _reemit
    custom_handler(event)
  File "/var/lib/juju/agents/unit-failover-0/charm/lib/charms/tls_certificates_interface/v3/tls_certificates.py", line 1911, in _on_relation_changed
    self.on.certificate_available.emit(
  File "/var/lib/juju/agents/unit-failover-0/charm/venv/ops/framework.py", line 348, in emit
    framework._emit(event)
  File "/var/lib/juju/agents/unit-failover-0/charm/venv/ops/framework.py", line 860, in _emit
    self._reemit(event_path)
  File "/var/lib/juju/agents/unit-failover-0/charm/venv/ops/framework.py", line 950, in _reemit
    custom_handler(event)
  File "/var/lib/juju/agents/unit-failover-0/charm/lib/charms/opensearch/v0/opensearch_tls.py", line 210, in _on_certificate_available
    if self._read_stored_ca() is None:
  File "/var/lib/juju/agents/unit-failover-0/charm/lib/charms/opensearch/v0/opensearch_tls.py", line 492, in _read_stored_ca
    stored_certs = run_cmd(
  File "/var/lib/juju/agents/unit-failover-0/charm/lib/charms/opensearch/v0/helper_charm.py", line 194, in run_cmd
    raise OpenSearchCmdError(cmd=command, out=output.stdout, err=output.stderr)
charms.opensearch.v0.opensearch_exceptions.OpenSearchCmdError
unit-failover-0: 03:00:51 ERROR juju.worker.uniter.operation hook "certificates-relation-changed" (via hook dispatching script: dispatch) failed: exit status 1
unit-failover-0: 03:05:51 ERROR unit.failover/0.juju-log certificates:14: err: Mac verify error: invalid password?
 / out: 
unit-failover-0: 03:05:51 ERROR unit.failover/0.juju-log certificates:14: Uncaught exception while in charm code:
Traceback (most recent call last):
  File "/var/lib/juju/agents/unit-failover-0/charm/./src/charm.py", line 213, in <module>
    main(OpenSearchOperatorCharm)
  File "/var/lib/juju/agents/unit-failover-0/charm/venv/ops/main.py", line 551, in main
    manager.run()
  File "/var/lib/juju/agents/unit-failover-0/charm/venv/ops/main.py", line 530, in run
    self._emit()
  File "/var/lib/juju/agents/unit-failover-0/charm/venv/ops/main.py", line 519, in _emit
    _emit_charm_event(self.charm, self.dispatcher.event_name)
  File "/var/lib/juju/agents/unit-failover-0/charm/venv/ops/main.py", line 147, in _emit_charm_event
    event_to_emit.emit(*args, **kwargs)
  File "/var/lib/juju/agents/unit-failover-0/charm/venv/ops/framework.py", line 348, in emit
    framework._emit(event)
  File "/var/lib/juju/agents/unit-failover-0/charm/venv/ops/framework.py", line 860, in _emit
    self._reemit(event_path)
  File "/var/lib/juju/agents/unit-failover-0/charm/venv/ops/framework.py", line 950, in _reemit
    custom_handler(event)
  File "/var/lib/juju/agents/unit-failover-0/charm/lib/charms/tls_certificates_interface/v3/tls_certificates.py", line 1911, in _on_relation_changed
    self.on.certificate_available.emit(
  File "/var/lib/juju/agents/unit-failover-0/charm/venv/ops/framework.py", line 348, in emit
    framework._emit(event)
  File "/var/lib/juju/agents/unit-failover-0/charm/venv/ops/framework.py", line 860, in _emit
    self._reemit(event_path)
  File "/var/lib/juju/agents/unit-failover-0/charm/venv/ops/framework.py", line 950, in _reemit
    custom_handler(event)
  File "/var/lib/juju/agents/unit-failover-0/charm/lib/charms/opensearch/v0/opensearch_tls.py", line 210, in _on_certificate_available
    if self._read_stored_ca() is None:
  File "/var/lib/juju/agents/unit-failover-0/charm/lib/charms/opensearch/v0/opensearch_tls.py", line 492, in _read_stored_ca
    stored_certs = run_cmd(
  File "/var/lib/juju/agents/unit-failover-0/charm/lib/charms/opensearch/v0/helper_charm.py", line 194, in run_cmd
    raise OpenSearchCmdError(cmd=command, out=output.stdout, err=output.stderr)
charms.opensearch.v0.opensearch_exceptions.OpenSearchCmdError
unit-failover-0: 03:05:51 ERROR juju.worker.uniter.operation hook "certificates-relation-changed" (via hook dispatching script: dispatch) failed: exit status 1
unit-failover-0: 03:10:52 ERROR unit.failover/0.juju-log certificates:14: err: Mac verify error: invalid password?
 / out: 
unit-failover-0: 03:10:52 ERROR unit.failover/0.juju-log certificates:14: Uncaught exception while in charm code:
Traceback (most recent call last):
  File "/var/lib/juju/agents/unit-failover-0/charm/./src/charm.py", line 213, in <module>
    main(OpenSearchOperatorCharm)
  File "/var/lib/juju/agents/unit-failover-0/charm/venv/ops/main.py", line 551, in main
    manager.run()
  File "/var/lib/juju/agents/unit-failover-0/charm/venv/ops/main.py", line 530, in run
    self._emit()
  File "/var/lib/juju/agents/unit-failover-0/charm/venv/ops/main.py", line 519, in _emit
    _emit_charm_event(self.charm, self.dispatcher.event_name)
  File "/var/lib/juju/agents/unit-failover-0/charm/venv/ops/main.py", line 147, in _emit_charm_event
    event_to_emit.emit(*args, **kwargs)
  File "/var/lib/juju/agents/unit-failover-0/charm/venv/ops/framework.py", line 348, in emit
    framework._emit(event)
  File "/var/lib/juju/agents/unit-failover-0/charm/venv/ops/framework.py", line 860, in _emit
    self._reemit(event_path)
  File "/var/lib/juju/agents/unit-failover-0/charm/venv/ops/framework.py", line 950, in _reemit
    custom_handler(event)
  File "/var/lib/juju/agents/unit-failover-0/charm/lib/charms/tls_certificates_interface/v3/tls_certificates.py", line 1911, in _on_relation_changed
    self.on.certificate_available.emit(
  File "/var/lib/juju/agents/unit-failover-0/charm/venv/ops/framework.py", line 348, in emit
    framework._emit(event)
  File "/var/lib/juju/agents/unit-failover-0/charm/venv/ops/framework.py", line 860, in _emit
    self._reemit(event_path)
  File "/var/lib/juju/agents/unit-failover-0/charm/venv/ops/framework.py", line 950, in _reemit
    custom_handler(event)
  File "/var/lib/juju/agents/unit-failover-0/charm/lib/charms/opensearch/v0/opensearch_tls.py", line 210, in _on_certificate_available
    if self._read_stored_ca() is None:
  File "/var/lib/juju/agents/unit-failover-0/charm/lib/charms/opensearch/v0/opensearch_tls.py", line 492, in _read_stored_ca
    stored_certs = run_cmd(
  File "/var/lib/juju/agents/unit-failover-0/charm/lib/charms/opensearch/v0/helper_charm.py", line 194, in run_cmd
    raise OpenSearchCmdError(cmd=command, out=output.stdout, err=output.stderr)
charms.opensearch.v0.opensearch_exceptions.OpenSearchCmdError
unit-failover-0: 03:10:52 ERROR juju.worker.uniter.operation hook "certificates-relation-changed" (via hook dispatching script: dispatch) failed: exit status 1
unit-failover-0: 03:15:53 ERROR unit.failover/0.juju-log certificates:14: err: Mac verify error: invalid password?
 / out: 
unit-failover-0: 03:15:53 ERROR unit.failover/0.juju-log certificates:14: Uncaught exception while in charm code:
Traceback (most recent call last):
  File "/var/lib/juju/agents/unit-failover-0/charm/./src/charm.py", line 213, in <module>
    main(OpenSearchOperatorCharm)
  File "/var/lib/juju/agents/unit-failover-0/charm/venv/ops/main.py", line 551, in main
    manager.run()
  File "/var/lib/juju/agents/unit-failover-0/charm/venv/ops/main.py", line 530, in run
    self._emit()
  File "/var/lib/juju/agents/unit-failover-0/charm/venv/ops/main.py", line 519, in _emit
    _emit_charm_event(self.charm, self.dispatcher.event_name)
  File "/var/lib/juju/agents/unit-failover-0/charm/venv/ops/main.py", line 147, in _emit_charm_event
    event_to_emit.emit(*args, **kwargs)
  File "/var/lib/juju/agents/unit-failover-0/charm/venv/ops/framework.py", line 348, in emit
    framework._emit(event)
  File "/var/lib/juju/agents/unit-failover-0/charm/venv/ops/framework.py", line 860, in _emit
    self._reemit(event_path)
  File "/var/lib/juju/agents/unit-failover-0/charm/venv/ops/framework.py", line 950, in _reemit
    custom_handler(event)
  File "/var/lib/juju/agents/unit-failover-0/charm/lib/charms/tls_certificates_interface/v3/tls_certificates.py", line 1911, in _on_relation_changed
    self.on.certificate_available.emit(
  File "/var/lib/juju/agents/unit-failover-0/charm/venv/ops/framework.py", line 348, in emit
    framework._emit(event)
  File "/var/lib/juju/agents/unit-failover-0/charm/venv/ops/framework.py", line 860, in _emit
    self._reemit(event_path)
  File "/var/lib/juju/agents/unit-failover-0/charm/venv/ops/framework.py", line 950, in _reemit
    custom_handler(event)
  File "/var/lib/juju/agents/unit-failover-0/charm/lib/charms/opensearch/v0/opensearch_tls.py", line 210, in _on_certificate_available
    if self._read_stored_ca() is None:
  File "/var/lib/juju/agents/unit-failover-0/charm/lib/charms/opensearch/v0/opensearch_tls.py", line 492, in _read_stored_ca
    stored_certs = run_cmd(
  File "/var/lib/juju/agents/unit-failover-0/charm/lib/charms/opensearch/v0/helper_charm.py", line 194, in run_cmd
    raise OpenSearchCmdError(cmd=command, out=output.stdout, err=output.stderr)
charms.opensearch.v0.opensearch_exceptions.OpenSearchCmdError
unit-failover-0: 03:15:53 ERROR juju.worker.uniter.operation hook "certificates-relation-changed" (via hook dispatching script: dispatch) failed: exit status 1
unit-failover-0: 03:20:54 ERROR unit.failover/0.juju-log certificates:14: err: Mac verify error: invalid password?
 / out: 
unit-failover-0: 03:20:54 ERROR unit.failover/0.juju-log certificates:14: Uncaught exception while in charm code:
Traceback (most recent call last):
  File "/var/lib/juju/agents/unit-failover-0/charm/./src/charm.py", line 213, in <module>
    main(OpenSearchOperatorCharm)
  File "/var/lib/juju/agents/unit-failover-0/charm/venv/ops/main.py", line 551, in main
    manager.run()
  File "/var/lib/juju/agents/unit-failover-0/charm/venv/ops/main.py", line 530, in run
    self._emit()
  File "/var/lib/juju/agents/unit-failover-0/charm/venv/ops/main.py", line 519, in _emit
    _emit_charm_event(self.charm, self.dispatcher.event_name)
  File "/var/lib/juju/agents/unit-failover-0/charm/venv/ops/main.py", line 147, in _emit_charm_event
    event_to_emit.emit(*args, **kwargs)
  File "/var/lib/juju/agents/unit-failover-0/charm/venv/ops/framework.py", line 348, in emit
    framework._emit(event)
  File "/var/lib/juju/agents/unit-failover-0/charm/venv/ops/framework.py", line 860, in _emit
    self._reemit(event_path)
  File "/var/lib/juju/agents/unit-failover-0/charm/venv/ops/framework.py", line 950, in _reemit
    custom_handler(event)
  File "/var/lib/juju/agents/unit-failover-0/charm/lib/charms/tls_certificates_interface/v3/tls_certificates.py", line 1911, in _on_relation_changed
    self.on.certificate_available.emit(
  File "/var/lib/juju/agents/unit-failover-0/charm/venv/ops/framework.py", line 348, in emit
    framework._emit(event)
  File "/var/lib/juju/agents/unit-failover-0/charm/venv/ops/framework.py", line 860, in _emit
    self._reemit(event_path)
  File "/var/lib/juju/agents/unit-failover-0/charm/venv/ops/framework.py", line 950, in _reemit
    custom_handler(event)
  File "/var/lib/juju/agents/unit-failover-0/charm/lib/charms/opensearch/v0/opensearch_tls.py", line 210, in _on_certificate_available
    if self._read_stored_ca() is None:
  File "/var/lib/juju/agents/unit-failover-0/charm/lib/charms/opensearch/v0/opensearch_tls.py", line 492, in _read_stored_ca
    stored_certs = run_cmd(
  File "/var/lib/juju/agents/unit-failover-0/charm/lib/charms/opensearch/v0/helper_charm.py", line 194, in run_cmd
    raise OpenSearchCmdError(cmd=command, out=output.stdout, err=output.stderr)
charms.opensearch.v0.opensearch_exceptions.OpenSearchCmdError
unit-failover-0: 03:20:54 ERROR juju.worker.uniter.operation hook "certificates-relation-changed" (via hook dispatching script: dispatch) failed: exit status 1
unit-failover-0: 03:25:55 ERROR unit.failover/0.juju-log certificates:14: err: Mac verify error: invalid password?
 / out: 
unit-failover-0: 03:25:55 ERROR unit.failover/0.juju-log certificates:14: Uncaught exception while in charm code:
Traceback (most recent call last):
  File "/var/lib/juju/agents/unit-failover-0/charm/./src/charm.py", line 213, in <module>
    main(OpenSearchOperatorCharm)
  File "/var/lib/juju/agents/unit-failover-0/charm/venv/ops/main.py", line 551, in main
    manager.run()
  File "/var/lib/juju/agents/unit-failover-0/charm/venv/ops/main.py", line 530, in run
    self._emit()
  File "/var/lib/juju/agents/unit-failover-0/charm/venv/ops/main.py", line 519, in _emit
    _emit_charm_event(self.charm, self.dispatcher.event_name)
  File "/var/lib/juju/agents/unit-failover-0/charm/venv/ops/main.py", line 147, in _emit_charm_event
    event_to_emit.emit(*args, **kwargs)
  File "/var/lib/juju/agents/unit-failover-0/charm/venv/ops/framework.py", line 348, in emit
    framework._emit(event)
  File "/var/lib/juju/agents/unit-failover-0/charm/venv/ops/framework.py", line 860, in _emit
    self._reemit(event_path)
  File "/var/lib/juju/agents/unit-failover-0/charm/venv/ops/framework.py", line 950, in _reemit
    custom_handler(event)
  File "/var/lib/juju/agents/unit-failover-0/charm/lib/charms/tls_certificates_interface/v3/tls_certificates.py", line 1911, in _on_relation_changed
    self.on.certificate_available.emit(
  File "/var/lib/juju/agents/unit-failover-0/charm/venv/ops/framework.py", line 348, in emit
    framework._emit(event)
  File "/var/lib/juju/agents/unit-failover-0/charm/venv/ops/framework.py", line 860, in _emit
    self._reemit(event_path)
  File "/var/lib/juju/agents/unit-failover-0/charm/venv/ops/framework.py", line 950, in _reemit
    custom_handler(event)
  File "/var/lib/juju/agents/unit-failover-0/charm/lib/charms/opensearch/v0/opensearch_tls.py", line 210, in _on_certificate_available
    if self._read_stored_ca() is None:
  File "/var/lib/juju/agents/unit-failover-0/charm/lib/charms/opensearch/v0/opensearch_tls.py", line 492, in _read_stored_ca
    stored_certs = run_cmd(
  File "/var/lib/juju/agents/unit-failover-0/charm/lib/charms/opensearch/v0/helper_charm.py", line 194, in run_cmd
    raise OpenSearchCmdError(cmd=command, out=output.stdout, err=output.stderr)
charms.opensearch.v0.opensearch_exceptions.OpenSearchCmdError
unit-failover-0: 03:25:55 ERROR juju.worker.uniter.operation hook "certificates-relation-changed" (via hook dispatching script: dispatch) failed: exit status 1
unit-failover-0: 03:30:56 ERROR unit.failover/0.juju-log certificates:14: err: Mac verify error: invalid password?
 / out: 
unit-failover-0: 03:30:56 ERROR unit.failover/0.juju-log certificates:14: Uncaught exception while in charm code:
Traceback (most recent call last):
  File "/var/lib/juju/agents/unit-failover-0/charm/./src/charm.py", line 213, in <module>
    main(OpenSearchOperatorCharm)
  File "/var/lib/juju/agents/unit-failover-0/charm/venv/ops/main.py", line 551, in main
    manager.run()
  File "/var/lib/juju/agents/unit-failover-0/charm/venv/ops/main.py", line 530, in run
    self._emit()
  File "/var/lib/juju/agents/unit-failover-0/charm/venv/ops/main.py", line 519, in _emit
    _emit_charm_event(self.charm, self.dispatcher.event_name)
  File "/var/lib/juju/agents/unit-failover-0/charm/venv/ops/main.py", line 147, in _emit_charm_event
    event_to_emit.emit(*args, **kwargs)
  File "/var/lib/juju/agents/unit-failover-0/charm/venv/ops/framework.py", line 348, in emit
    framework._emit(event)
  File "/var/lib/juju/agents/unit-failover-0/charm/venv/ops/framework.py", line 860, in _emit
    self._reemit(event_path)
  File "/var/lib/juju/agents/unit-failover-0/charm/venv/ops/framework.py", line 950, in _reemit
    custom_handler(event)
  File "/var/lib/juju/agents/unit-failover-0/charm/lib/charms/tls_certificates_interface/v3/tls_certificates.py", line 1911, in _on_relation_changed
    self.on.certificate_available.emit(
  File "/var/lib/juju/agents/unit-failover-0/charm/venv/ops/framework.py", line 348, in emit
    framework._emit(event)
  File "/var/lib/juju/agents/unit-failover-0/charm/venv/ops/framework.py", line 860, in _emit
    self._reemit(event_path)
  File "/var/lib/juju/agents/unit-failover-0/charm/venv/ops/framework.py", line 950, in _reemit
    custom_handler(event)
  File "/var/lib/juju/agents/unit-failover-0/charm/lib/charms/opensearch/v0/opensearch_tls.py", line 210, in _on_certificate_available
    if self._read_stored_ca() is None:
  File "/var/lib/juju/agents/unit-failover-0/charm/lib/charms/opensearch/v0/opensearch_tls.py", line 492, in _read_stored_ca
    stored_certs = run_cmd(
  File "/var/lib/juju/agents/unit-failover-0/charm/lib/charms/opensearch/v0/helper_charm.py", line 194, in run_cmd
    raise OpenSearchCmdError(cmd=command, out=output.stdout, err=output.stderr)
charms.opensearch.v0.opensearch_exceptions.OpenSearchCmdError
unit-failover-0: 03:30:56 ERROR juju.worker.uniter.operation hook "certificates-relation-changed" (via hook dispatching script: dispatch) failed: exit status 1
unit-failover-0: 03:35:57 ERROR unit.failover/0.juju-log certificates:14: err: Mac verify error: invalid password?
 / out: 
unit-failover-0: 03:35:57 ERROR unit.failover/0.juju-log certificates:14: Uncaught exception while in charm code:
Traceback (most recent call last):
  File "/var/lib/juju/agents/unit-failover-0/charm/./src/charm.py", line 213, in <module>
    main(OpenSearchOperatorCharm)
  File "/var/lib/juju/agents/unit-failover-0/charm/venv/ops/main.py", line 551, in main
    manager.run()
  File "/var/lib/juju/agents/unit-failover-0/charm/venv/ops/main.py", line 530, in run
    self._emit()
  File "/var/lib/juju/agents/unit-failover-0/charm/venv/ops/main.py", line 519, in _emit
    _emit_charm_event(self.charm, self.dispatcher.event_name)
  File "/var/lib/juju/agents/unit-failover-0/charm/venv/ops/main.py", line 147, in _emit_charm_event
    event_to_emit.emit(*args, **kwargs)
  File "/var/lib/juju/agents/unit-failover-0/charm/venv/ops/framework.py", line 348, in emit
    framework._emit(event)
  File "/var/lib/juju/agents/unit-failover-0/charm/venv/ops/framework.py", line 860, in _emit
    self._reemit(event_path)
  File "/var/lib/juju/agents/unit-failover-0/charm/venv/ops/framework.py", line 950, in _reemit
    custom_handler(event)
  File "/var/lib/juju/agents/unit-failover-0/charm/lib/charms/tls_certificates_interface/v3/tls_certificates.py", line 1911, in _on_relation_changed
    self.on.certificate_available.emit(
  File "/var/lib/juju/agents/unit-failover-0/charm/venv/ops/framework.py", line 348, in emit
    framework._emit(event)
  File "/var/lib/juju/agents/unit-failover-0/charm/venv/ops/framework.py", line 860, in _emit
    self._reemit(event_path)
  File "/var/lib/juju/agents/unit-failover-0/charm/venv/ops/framework.py", line 950, in _reemit
    custom_handler(event)
  File "/var/lib/juju/agents/unit-failover-0/charm/lib/charms/opensearch/v0/opensearch_tls.py", line 210, in _on_certificate_available
    if self._read_stored_ca() is None:
  File "/var/lib/juju/agents/unit-failover-0/charm/lib/charms/opensearch/v0/opensearch_tls.py", line 492, in _read_stored_ca
    stored_certs = run_cmd(
  File "/var/lib/juju/agents/unit-failover-0/charm/lib/charms/opensearch/v0/helper_charm.py", line 194, in run_cmd
    raise OpenSearchCmdError(cmd=command, out=output.stdout, err=output.stderr)
charms.opensearch.v0.opensearch_exceptions.OpenSearchCmdError
unit-failover-0: 03:35:57 ERROR juju.worker.uniter.operation hook "certificates-relation-changed" (via hook dispatching script: dispatch) failed: exit status 1
unit-failover-0: 03:40:58 ERROR unit.failover/0.juju-log certificates:14: err: Mac verify error: invalid password?
 / out: 
unit-failover-0: 03:40:58 ERROR unit.failover/0.juju-log certificates:14: Uncaught exception while in charm code:
Traceback (most recent call last):
  File "/var/lib/juju/agents/unit-failover-0/charm/./src/charm.py", line 213, in <module>
    main(OpenSearchOperatorCharm)
  File "/var/lib/juju/agents/unit-failover-0/charm/venv/ops/main.py", line 551, in main
    manager.run()
  File "/var/lib/juju/agents/unit-failover-0/charm/venv/ops/main.py", line 530, in run
    self._emit()
  File "/var/lib/juju/agents/unit-failover-0/charm/venv/ops/main.py", line 519, in _emit
    _emit_charm_event(self.charm, self.dispatcher.event_name)
  File "/var/lib/juju/agents/unit-failover-0/charm/venv/ops/main.py", line 147, in _emit_charm_event
    event_to_emit.emit(*args, **kwargs)
  File "/var/lib/juju/agents/unit-failover-0/charm/venv/ops/framework.py", line 348, in emit
    framework._emit(event)
  File "/var/lib/juju/agents/unit-failover-0/charm/venv/ops/framework.py", line 860, in _emit
    self._reemit(event_path)
  File "/var/lib/juju/agents/unit-failover-0/charm/venv/ops/framework.py", line 950, in _reemit
    custom_handler(event)
  File "/var/lib/juju/agents/unit-failover-0/charm/lib/charms/tls_certificates_interface/v3/tls_certificates.py", line 1911, in _on_relation_changed
    self.on.certificate_available.emit(
  File "/var/lib/juju/agents/unit-failover-0/charm/venv/ops/framework.py", line 348, in emit
    framework._emit(event)
  File "/var/lib/juju/agents/unit-failover-0/charm/venv/ops/framework.py", line 860, in _emit
    self._reemit(event_path)
  File "/var/lib/juju/agents/unit-failover-0/charm/venv/ops/framework.py", line 950, in _reemit
    custom_handler(event)
  File "/var/lib/juju/agents/unit-failover-0/charm/lib/charms/opensearch/v0/opensearch_tls.py", line 210, in _on_certificate_available
    if self._read_stored_ca() is None:
  File "/var/lib/juju/agents/unit-failover-0/charm/lib/charms/opensearch/v0/opensearch_tls.py", line 492, in _read_stored_ca
    stored_certs = run_cmd(
  File "/var/lib/juju/agents/unit-failover-0/charm/lib/charms/opensearch/v0/helper_charm.py", line 194, in run_cmd
    raise OpenSearchCmdError(cmd=command, out=output.stdout, err=output.stderr)
charms.opensearch.v0.opensearch_exceptions.OpenSearchCmdError
unit-failover-0: 03:40:58 ERROR juju.worker.uniter.operation hook "certificates-relation-changed" (via hook dispatching script: dispatch) failed: exit status 1

[32mINFO    [0m pytest_operator.plugin:plugin.py:947 Forgetting model main...
[32mINFO    [0m integration.ha.test_backups:test_backups.py:173 Cleaning backups from cloud buckets