[32mINFO    [0m integration.ha.test_backups:test_backups.py:440 Syncing credentials for microceph
[32mINFO    [0m juju.model:model.py:2971 Waiting for model:
  main/0 [executing] maintenance: Configuring backup service...
  s3-integrator/0 [idle] active: 
[32mINFO    [0m juju.model:model.py:2971 Waiting for model:
  main/0 [idle] active: 
[32mINFO    [0m integration.helpers:helpers.py:347 Calling: GET -- https://10.241.98.215:9200/_recovery?human
[32mINFO    [0m integration.ha.helpers:helpers.py:247 Continuous writes result: namespace(max_stored_id=172, count=173, last_expected_id=172)
[32mINFO    [0m integration.helpers:helpers.py:347 Calling: GET -- https://10.241.98.215:9200/series_index/_search_shards
[32mINFO    [0m integration.helpers:helpers.py:347 Calling: POST -- https://10.241.98.215:9200/series_index/_refresh
[32mINFO    [0m integration.helpers:helpers.py:347 Calling: GET -- https://10.241.98.215:9200/series_index/_count
[32mINFO    [0m integration.helpers:helpers.py:347 Calling: GET -- https://10.241.98.215:9200/_recovery?human
[32mINFO    [0m integration.helpers:helpers.py:347 Calling: POST -- https://10.241.98.215:9200/series_index/_refresh
[32mINFO    [0m integration.helpers:helpers.py:347 Calling: GET -- https://10.241.98.215:9200/series_index/_count
[32mINFO    [0m integration.ha.helpers:helpers.py:591 Testing restore for series_index - original count pre-restore: 173, and now, new count: 143
[32mINFO    [0m integration.helpers:helpers.py:347 Calling: POST -- https://10.241.98.215:9200/series_index/_refresh
[32mINFO    [0m integration.helpers:helpers.py:347 Calling: GET -- https://10.241.98.215:9200/series_index/_count
[32mINFO    [0m integration.ha.conftest:conftest.py:39 



The writes have been cleared.